[2022-02-15 03:14:08,098] {taskinstance.py:1032} INFO - Dependencies all met for <TaskInstance: dbt_training_bytecode.model.my_new_project.all_dates manual__2022-02-15T03:14:06.780838+00:00 [queued]>
[2022-02-15 03:14:08,112] {taskinstance.py:1032} INFO - Dependencies all met for <TaskInstance: dbt_training_bytecode.model.my_new_project.all_dates manual__2022-02-15T03:14:06.780838+00:00 [queued]>
[2022-02-15 03:14:08,113] {taskinstance.py:1238} INFO - 
--------------------------------------------------------------------------------
[2022-02-15 03:14:08,115] {taskinstance.py:1239} INFO - Starting attempt 1 of 1
[2022-02-15 03:14:08,116] {taskinstance.py:1240} INFO - 
--------------------------------------------------------------------------------
[2022-02-15 03:14:08,138] {taskinstance.py:1259} INFO - Executing <Task(BashOperator): model.my_new_project.all_dates> on 2022-02-15 03:14:06.780838+00:00
[2022-02-15 03:14:08,144] {standard_task_runner.py:52} INFO - Started process 1118 to run task
[2022-02-15 03:14:08,150] {standard_task_runner.py:76} INFO - Running: ['***', 'tasks', 'run', 'dbt_training_bytecode', 'model.my_new_project.all_dates', 'manual__2022-02-15T03:14:06.780838+00:00', '--job-id', '104', '--raw', '--subdir', 'DAGS_FOLDER/dbt-***.py', '--cfg-path', '/tmp/tmpwgnccei6', '--error-file', '/tmp/tmplbtjhgkl']
[2022-02-15 03:14:08,152] {standard_task_runner.py:77} INFO - Job 104: Subtask model.my_new_project.all_dates
[2022-02-15 03:14:08,301] {logging_mixin.py:109} INFO - Running <TaskInstance: dbt_training_bytecode.model.my_new_project.all_dates manual__2022-02-15T03:14:06.780838+00:00 [running]> on host 459d09dd7c86
[2022-02-15 03:14:08,468] {taskinstance.py:1426} INFO - Exporting the following env vars:
AIRFLOW_CTX_DAG_OWNER=Bytecode
AIRFLOW_CTX_DAG_ID=dbt_training_bytecode
AIRFLOW_CTX_TASK_ID=model.my_new_project.all_dates
AIRFLOW_CTX_EXECUTION_DATE=2022-02-15T03:14:06.780838+00:00
AIRFLOW_CTX_DAG_RUN_ID=manual__2022-02-15T03:14:06.780838+00:00
[2022-02-15 03:14:08,476] {subprocess.py:62} INFO - Tmp dir root location: 
 /tmp
[2022-02-15 03:14:08,486] {subprocess.py:74} INFO - Running command: ['bash', '-c', '\n            dbt --no-write-json run --target dev --models all_dates             --profiles-dir /opt/***/dbt/dbt-training-bytecode-1 --project-dir /opt/***/dbt/dbt-training-bytecode-1\n            ']
[2022-02-15 03:14:08,520] {subprocess.py:85} INFO - Output:
[2022-02-15 03:14:16,401] {subprocess.py:89} INFO - 03:14:16  Running with dbt=1.0.1
[2022-02-15 03:14:16,498] {subprocess.py:89} INFO - 03:14:16  Unable to do partial parsing because config vars, config profile, or config target have changed
[2022-02-15 03:14:20,668] {subprocess.py:89} INFO - 03:14:20  Encountered an error:
[2022-02-15 03:14:20,670] {subprocess.py:89} INFO - [Errno 2] No such file or directory: '/opt/***/dbt/dbt-training-bytecode-1/dbt_packages/dbt_utils/dbt_project.yml'
[2022-02-15 03:14:21,057] {subprocess.py:93} INFO - Command exited with return code 2
[2022-02-15 03:14:21,077] {taskinstance.py:1700} ERROR - Task failed with exception
Traceback (most recent call last):
  File "/home/airflow/.local/lib/python3.7/site-packages/airflow/models/taskinstance.py", line 1329, in _run_raw_task
    self._execute_task_with_callbacks(context)
  File "/home/airflow/.local/lib/python3.7/site-packages/airflow/models/taskinstance.py", line 1455, in _execute_task_with_callbacks
    result = self._execute_task(context, self.task)
  File "/home/airflow/.local/lib/python3.7/site-packages/airflow/models/taskinstance.py", line 1511, in _execute_task
    result = execute_callable(context=context)
  File "/home/airflow/.local/lib/python3.7/site-packages/airflow/operators/bash.py", line 188, in execute
    f'Bash command failed. The command returned a non-zero exit code {result.exit_code}.'
airflow.exceptions.AirflowException: Bash command failed. The command returned a non-zero exit code 2.
[2022-02-15 03:14:21,092] {taskinstance.py:1277} INFO - Marking task as FAILED. dag_id=dbt_training_bytecode, task_id=model.my_new_project.all_dates, execution_date=20220215T031406, start_date=20220215T031408, end_date=20220215T031421
[2022-02-15 03:14:21,120] {standard_task_runner.py:92} ERROR - Failed to execute job 104 for task model.my_new_project.all_dates
Traceback (most recent call last):
  File "/home/airflow/.local/lib/python3.7/site-packages/airflow/task/task_runner/standard_task_runner.py", line 85, in _start_by_fork
    args.func(args, dag=self.dag)
  File "/home/airflow/.local/lib/python3.7/site-packages/airflow/cli/cli_parser.py", line 48, in command
    return func(*args, **kwargs)
  File "/home/airflow/.local/lib/python3.7/site-packages/airflow/utils/cli.py", line 92, in wrapper
    return f(*args, **kwargs)
  File "/home/airflow/.local/lib/python3.7/site-packages/airflow/cli/commands/task_command.py", line 298, in task_run
    _run_task_by_selected_method(args, dag, ti)
  File "/home/airflow/.local/lib/python3.7/site-packages/airflow/cli/commands/task_command.py", line 107, in _run_task_by_selected_method
    _run_raw_task(args, ti)
  File "/home/airflow/.local/lib/python3.7/site-packages/airflow/cli/commands/task_command.py", line 184, in _run_raw_task
    error_file=args.error_file,
  File "/home/airflow/.local/lib/python3.7/site-packages/airflow/utils/session.py", line 70, in wrapper
    return func(*args, session=session, **kwargs)
  File "/home/airflow/.local/lib/python3.7/site-packages/airflow/models/taskinstance.py", line 1329, in _run_raw_task
    self._execute_task_with_callbacks(context)
  File "/home/airflow/.local/lib/python3.7/site-packages/airflow/models/taskinstance.py", line 1455, in _execute_task_with_callbacks
    result = self._execute_task(context, self.task)
  File "/home/airflow/.local/lib/python3.7/site-packages/airflow/models/taskinstance.py", line 1511, in _execute_task
    result = execute_callable(context=context)
  File "/home/airflow/.local/lib/python3.7/site-packages/airflow/operators/bash.py", line 188, in execute
    f'Bash command failed. The command returned a non-zero exit code {result.exit_code}.'
airflow.exceptions.AirflowException: Bash command failed. The command returned a non-zero exit code 2.
[2022-02-15 03:14:21,162] {local_task_job.py:154} INFO - Task exited with return code 1
[2022-02-15 03:14:21,252] {local_task_job.py:264} INFO - 0 downstream tasks scheduled from follow-on schedule check
