[2022-02-15 03:06:29,682] {taskinstance.py:1032} INFO - Dependencies all met for <TaskInstance: dbt_training_bytecode.model.my_new_project.mart_orders manual__2022-02-15T03:04:57.520087+00:00 [queued]>
[2022-02-15 03:06:29,696] {taskinstance.py:1032} INFO - Dependencies all met for <TaskInstance: dbt_training_bytecode.model.my_new_project.mart_orders manual__2022-02-15T03:04:57.520087+00:00 [queued]>
[2022-02-15 03:06:29,697] {taskinstance.py:1238} INFO - 
--------------------------------------------------------------------------------
[2022-02-15 03:06:29,698] {taskinstance.py:1239} INFO - Starting attempt 1 of 1
[2022-02-15 03:06:29,699] {taskinstance.py:1240} INFO - 
--------------------------------------------------------------------------------
[2022-02-15 03:06:29,714] {taskinstance.py:1259} INFO - Executing <Task(BashOperator): model.my_new_project.mart_orders> on 2022-02-15 03:04:57.520087+00:00
[2022-02-15 03:06:29,719] {standard_task_runner.py:52} INFO - Started process 726 to run task
[2022-02-15 03:06:29,728] {standard_task_runner.py:76} INFO - Running: ['***', 'tasks', 'run', 'dbt_training_bytecode', 'model.my_new_project.mart_orders', 'manual__2022-02-15T03:04:57.520087+00:00', '--job-id', '101', '--raw', '--subdir', 'DAGS_FOLDER/dbt-***.py', '--cfg-path', '/tmp/tmpn83k5ywi', '--error-file', '/tmp/tmpsm2_osn9']
[2022-02-15 03:06:29,729] {standard_task_runner.py:77} INFO - Job 101: Subtask model.my_new_project.mart_orders
[2022-02-15 03:06:29,807] {logging_mixin.py:109} INFO - Running <TaskInstance: dbt_training_bytecode.model.my_new_project.mart_orders manual__2022-02-15T03:04:57.520087+00:00 [running]> on host 459d09dd7c86
[2022-02-15 03:06:29,877] {taskinstance.py:1426} INFO - Exporting the following env vars:
AIRFLOW_CTX_DAG_OWNER=Bytecode
AIRFLOW_CTX_DAG_ID=dbt_training_bytecode
AIRFLOW_CTX_TASK_ID=model.my_new_project.mart_orders
AIRFLOW_CTX_EXECUTION_DATE=2022-02-15T03:04:57.520087+00:00
AIRFLOW_CTX_DAG_RUN_ID=manual__2022-02-15T03:04:57.520087+00:00
[2022-02-15 03:06:29,879] {subprocess.py:62} INFO - Tmp dir root location: 
 /tmp
[2022-02-15 03:06:29,880] {subprocess.py:74} INFO - Running command: ['bash', '-c', '\n            dbt --no-write-json run --target dev --models mart_orders             --profiles-dir /opt/***/dbt/dbt-training-bytecode-1 --project-dir /opt/***/dbt/dbt-training-bytecode-1\n            ']
[2022-02-15 03:06:29,894] {subprocess.py:85} INFO - Output:
[2022-02-15 03:06:35,423] {subprocess.py:89} INFO - 03:06:35  Running with dbt=1.0.1
[2022-02-15 03:06:35,852] {subprocess.py:89} INFO - 03:06:35  Found 8 models, 11 tests, 0 snapshots, 0 analyses, 367 macros, 0 operations, 1 seed file, 3 sources, 0 exposures, 0 metrics
[2022-02-15 03:06:35,859] {subprocess.py:89} INFO - 03:06:35
[2022-02-15 03:06:39,725] {subprocess.py:89} INFO - 03:06:39  Concurrency: 4 threads (target='dev')
[2022-02-15 03:06:39,728] {subprocess.py:89} INFO - 03:06:39
[2022-02-15 03:06:39,743] {subprocess.py:89} INFO - 03:06:39  1 of 1 START view model dbt_bytecode_training.mart_orders....................... [RUN]
[2022-02-15 03:06:41,461] {subprocess.py:89} INFO - 03:06:41  1 of 1 ERROR creating view model dbt_bytecode_training.mart_orders.............. [ERROR in 1.71s]
[2022-02-15 03:06:41,573] {subprocess.py:89} INFO - 03:06:41
[2022-02-15 03:06:41,576] {subprocess.py:89} INFO - 03:06:41  Finished running 1 view model in 5.71s.
[2022-02-15 03:06:41,582] {subprocess.py:89} INFO - 03:06:41
[2022-02-15 03:06:41,584] {subprocess.py:89} INFO - 03:06:41  Completed with 1 error and 0 warnings:
[2022-02-15 03:06:41,587] {subprocess.py:89} INFO - 03:06:41
[2022-02-15 03:06:41,589] {subprocess.py:89} INFO - 03:06:41  Database Error in model mart_orders (models/marts/mart_orders.sql)
[2022-02-15 03:06:41,591] {subprocess.py:89} INFO - 03:06:41    002025 (42S21): SQL compilation error:
[2022-02-15 03:06:41,593] {subprocess.py:89} INFO - 03:06:41    duplicate column name 'CUSTOMER_ID'
[2022-02-15 03:06:41,595] {subprocess.py:89} INFO - 03:06:41    compiled SQL at target/run/my_new_project/models/marts/mart_orders.sql
[2022-02-15 03:06:41,597] {subprocess.py:89} INFO - 03:06:41
[2022-02-15 03:06:41,599] {subprocess.py:89} INFO - 03:06:41  Done. PASS=0 WARN=0 ERROR=1 SKIP=0 TOTAL=1
[2022-02-15 03:06:42,015] {subprocess.py:93} INFO - Command exited with return code 1
[2022-02-15 03:06:42,031] {taskinstance.py:1700} ERROR - Task failed with exception
Traceback (most recent call last):
  File "/home/airflow/.local/lib/python3.7/site-packages/airflow/models/taskinstance.py", line 1329, in _run_raw_task
    self._execute_task_with_callbacks(context)
  File "/home/airflow/.local/lib/python3.7/site-packages/airflow/models/taskinstance.py", line 1455, in _execute_task_with_callbacks
    result = self._execute_task(context, self.task)
  File "/home/airflow/.local/lib/python3.7/site-packages/airflow/models/taskinstance.py", line 1511, in _execute_task
    result = execute_callable(context=context)
  File "/home/airflow/.local/lib/python3.7/site-packages/airflow/operators/bash.py", line 188, in execute
    f'Bash command failed. The command returned a non-zero exit code {result.exit_code}.'
airflow.exceptions.AirflowException: Bash command failed. The command returned a non-zero exit code 1.
[2022-02-15 03:06:42,038] {taskinstance.py:1277} INFO - Marking task as FAILED. dag_id=dbt_training_bytecode, task_id=model.my_new_project.mart_orders, execution_date=20220215T030457, start_date=20220215T030629, end_date=20220215T030642
[2022-02-15 03:06:42,053] {standard_task_runner.py:92} ERROR - Failed to execute job 101 for task model.my_new_project.mart_orders
Traceback (most recent call last):
  File "/home/airflow/.local/lib/python3.7/site-packages/airflow/task/task_runner/standard_task_runner.py", line 85, in _start_by_fork
    args.func(args, dag=self.dag)
  File "/home/airflow/.local/lib/python3.7/site-packages/airflow/cli/cli_parser.py", line 48, in command
    return func(*args, **kwargs)
  File "/home/airflow/.local/lib/python3.7/site-packages/airflow/utils/cli.py", line 92, in wrapper
    return f(*args, **kwargs)
  File "/home/airflow/.local/lib/python3.7/site-packages/airflow/cli/commands/task_command.py", line 298, in task_run
    _run_task_by_selected_method(args, dag, ti)
  File "/home/airflow/.local/lib/python3.7/site-packages/airflow/cli/commands/task_command.py", line 107, in _run_task_by_selected_method
    _run_raw_task(args, ti)
  File "/home/airflow/.local/lib/python3.7/site-packages/airflow/cli/commands/task_command.py", line 184, in _run_raw_task
    error_file=args.error_file,
  File "/home/airflow/.local/lib/python3.7/site-packages/airflow/utils/session.py", line 70, in wrapper
    return func(*args, session=session, **kwargs)
  File "/home/airflow/.local/lib/python3.7/site-packages/airflow/models/taskinstance.py", line 1329, in _run_raw_task
    self._execute_task_with_callbacks(context)
  File "/home/airflow/.local/lib/python3.7/site-packages/airflow/models/taskinstance.py", line 1455, in _execute_task_with_callbacks
    result = self._execute_task(context, self.task)
  File "/home/airflow/.local/lib/python3.7/site-packages/airflow/models/taskinstance.py", line 1511, in _execute_task
    result = execute_callable(context=context)
  File "/home/airflow/.local/lib/python3.7/site-packages/airflow/operators/bash.py", line 188, in execute
    f'Bash command failed. The command returned a non-zero exit code {result.exit_code}.'
airflow.exceptions.AirflowException: Bash command failed. The command returned a non-zero exit code 1.
[2022-02-15 03:06:42,100] {local_task_job.py:154} INFO - Task exited with return code 1
[2022-02-15 03:06:42,152] {local_task_job.py:264} INFO - 0 downstream tasks scheduled from follow-on schedule check
