[2022-02-15 03:02:06,033] {taskinstance.py:1032} INFO - Dependencies all met for <TaskInstance: dbt_compile.dbt_compile manual__2022-02-15T03:02:04.924850+00:00 [queued]>
[2022-02-15 03:02:06,043] {taskinstance.py:1032} INFO - Dependencies all met for <TaskInstance: dbt_compile.dbt_compile manual__2022-02-15T03:02:04.924850+00:00 [queued]>
[2022-02-15 03:02:06,043] {taskinstance.py:1238} INFO - 
--------------------------------------------------------------------------------
[2022-02-15 03:02:06,044] {taskinstance.py:1239} INFO - Starting attempt 1 of 1
[2022-02-15 03:02:06,045] {taskinstance.py:1240} INFO - 
--------------------------------------------------------------------------------
[2022-02-15 03:02:06,055] {taskinstance.py:1259} INFO - Executing <Task(BashOperator): dbt_compile> on 2022-02-15 03:02:04.924850+00:00
[2022-02-15 03:02:06,060] {standard_task_runner.py:52} INFO - Started process 198 to run task
[2022-02-15 03:02:06,064] {standard_task_runner.py:76} INFO - Running: ['***', 'tasks', 'run', 'dbt_compile', 'dbt_compile', 'manual__2022-02-15T03:02:04.924850+00:00', '--job-id', '84', '--raw', '--subdir', 'DAGS_FOLDER/dbt_compile.py', '--cfg-path', '/tmp/tmp5gz53qxb', '--error-file', '/tmp/tmpf4fx0pbk']
[2022-02-15 03:02:06,065] {standard_task_runner.py:77} INFO - Job 84: Subtask dbt_compile
[2022-02-15 03:02:06,122] {logging_mixin.py:109} INFO - Running <TaskInstance: dbt_compile.dbt_compile manual__2022-02-15T03:02:04.924850+00:00 [running]> on host 459d09dd7c86
[2022-02-15 03:02:06,173] {taskinstance.py:1426} INFO - Exporting the following env vars:
AIRFLOW_CTX_DAG_OWNER=Bytecode
AIRFLOW_CTX_DAG_ID=dbt_compile
AIRFLOW_CTX_TASK_ID=dbt_compile
AIRFLOW_CTX_EXECUTION_DATE=2022-02-15T03:02:04.924850+00:00
AIRFLOW_CTX_DAG_RUN_ID=manual__2022-02-15T03:02:04.924850+00:00
[2022-02-15 03:02:06,174] {subprocess.py:62} INFO - Tmp dir root location: 
 /tmp
[2022-02-15 03:02:06,175] {subprocess.py:74} INFO - Running command: ['bash', '-c', 'dbt compile --profiles-dir /usr/local/***/dbt/dbt-training-bytecode-1 --project-dir /usr/local/***/dbt/dbt-training-bytecode-1']
[2022-02-15 03:02:06,185] {subprocess.py:85} INFO - Output:
[2022-02-15 03:02:09,484] {subprocess.py:89} INFO - 03:02:09  Encountered an error:
[2022-02-15 03:02:09,485] {subprocess.py:89} INFO - Runtime Error
[2022-02-15 03:02:09,486] {subprocess.py:89} INFO -   fatal: Invalid --project-dir flag. Not a dbt project. Missing dbt_project.yml file
[2022-02-15 03:02:09,578] {subprocess.py:93} INFO - Command exited with return code 2
[2022-02-15 03:02:09,596] {taskinstance.py:1700} ERROR - Task failed with exception
Traceback (most recent call last):
  File "/home/airflow/.local/lib/python3.7/site-packages/airflow/models/taskinstance.py", line 1329, in _run_raw_task
    self._execute_task_with_callbacks(context)
  File "/home/airflow/.local/lib/python3.7/site-packages/airflow/models/taskinstance.py", line 1455, in _execute_task_with_callbacks
    result = self._execute_task(context, self.task)
  File "/home/airflow/.local/lib/python3.7/site-packages/airflow/models/taskinstance.py", line 1511, in _execute_task
    result = execute_callable(context=context)
  File "/home/airflow/.local/lib/python3.7/site-packages/airflow/operators/bash.py", line 188, in execute
    f'Bash command failed. The command returned a non-zero exit code {result.exit_code}.'
airflow.exceptions.AirflowException: Bash command failed. The command returned a non-zero exit code 2.
[2022-02-15 03:02:09,606] {taskinstance.py:1277} INFO - Marking task as FAILED. dag_id=dbt_compile, task_id=dbt_compile, execution_date=20220215T030204, start_date=20220215T030206, end_date=20220215T030209
[2022-02-15 03:02:09,623] {standard_task_runner.py:92} ERROR - Failed to execute job 84 for task dbt_compile
Traceback (most recent call last):
  File "/home/airflow/.local/lib/python3.7/site-packages/airflow/task/task_runner/standard_task_runner.py", line 85, in _start_by_fork
    args.func(args, dag=self.dag)
  File "/home/airflow/.local/lib/python3.7/site-packages/airflow/cli/cli_parser.py", line 48, in command
    return func(*args, **kwargs)
  File "/home/airflow/.local/lib/python3.7/site-packages/airflow/utils/cli.py", line 92, in wrapper
    return f(*args, **kwargs)
  File "/home/airflow/.local/lib/python3.7/site-packages/airflow/cli/commands/task_command.py", line 298, in task_run
    _run_task_by_selected_method(args, dag, ti)
  File "/home/airflow/.local/lib/python3.7/site-packages/airflow/cli/commands/task_command.py", line 107, in _run_task_by_selected_method
    _run_raw_task(args, ti)
  File "/home/airflow/.local/lib/python3.7/site-packages/airflow/cli/commands/task_command.py", line 184, in _run_raw_task
    error_file=args.error_file,
  File "/home/airflow/.local/lib/python3.7/site-packages/airflow/utils/session.py", line 70, in wrapper
    return func(*args, session=session, **kwargs)
  File "/home/airflow/.local/lib/python3.7/site-packages/airflow/models/taskinstance.py", line 1329, in _run_raw_task
    self._execute_task_with_callbacks(context)
  File "/home/airflow/.local/lib/python3.7/site-packages/airflow/models/taskinstance.py", line 1455, in _execute_task_with_callbacks
    result = self._execute_task(context, self.task)
  File "/home/airflow/.local/lib/python3.7/site-packages/airflow/models/taskinstance.py", line 1511, in _execute_task
    result = execute_callable(context=context)
  File "/home/airflow/.local/lib/python3.7/site-packages/airflow/operators/bash.py", line 188, in execute
    f'Bash command failed. The command returned a non-zero exit code {result.exit_code}.'
airflow.exceptions.AirflowException: Bash command failed. The command returned a non-zero exit code 2.
[2022-02-15 03:02:09,661] {local_task_job.py:154} INFO - Task exited with return code 1
[2022-02-15 03:02:09,690] {local_task_job.py:264} INFO - 0 downstream tasks scheduled from follow-on schedule check
